Starting epoch 1/100...
Epoch 1:   0%|                                               | 0/42476 [01:06<?, ?it/s]
Traceback (most recent call last):
  File "/root/miniconda3/envs/rewas/lib/python3.10/site-packages/torch/utils/data/dataloader.py", line 1243, in _try_get_data
    data = self._data_queue.get(timeout=timeout)
  File "/root/miniconda3/envs/rewas/lib/python3.10/queue.py", line 180, in get
    self.not_empty.wait(remaining)
  File "/root/miniconda3/envs/rewas/lib/python3.10/threading.py", line 324, in wait
    gotit = waiter.acquire(True, timeout)
  File "/root/miniconda3/envs/rewas/lib/python3.10/site-packages/torch/utils/data/_utils/signal_handling.py", line 73, in handler
    _error_if_any_worker_fails()
RuntimeError: DataLoader worker (pid 363747) is killed by signal: Bus error. It is possible that dataloader's workers are out of shared memory. Please try to raise your shared memory limit.

The above exception was the direct cause of the following exception:

Traceback (most recent call last):
  File "/workspace/rewas/./train_miil.py", line 329, in <module>
    main(args)
  File "/workspace/rewas/./train_miil.py", line 144, in main
    for step, batch in enumerate(tqdm(train_loader, desc=f"Epoch {epoch + 1}")):
  File "/root/miniconda3/envs/rewas/lib/python3.10/site-packages/tqdm/std.py", line 1181, in __iter__
    for obj in iterable:
  File "/root/miniconda3/envs/rewas/lib/python3.10/site-packages/accelerate/data_loader.py", line 552, in __iter__
    current_batch = next(dataloader_iter)
  File "/root/miniconda3/envs/rewas/lib/python3.10/site-packages/torch/utils/data/dataloader.py", line 701, in __next__
    data = self._next_data()
  File "/root/miniconda3/envs/rewas/lib/python3.10/site-packages/torch/utils/data/dataloader.py", line 1448, in _next_data
    idx, data = self._get_data()
  File "/root/miniconda3/envs/rewas/lib/python3.10/site-packages/torch/utils/data/dataloader.py", line 1402, in _get_data
    success, data = self._try_get_data()
  File "/root/miniconda3/envs/rewas/lib/python3.10/site-packages/torch/utils/data/dataloader.py", line 1256, in _try_get_data
    raise RuntimeError(
RuntimeError: DataLoader worker (pid(s) 363747) exited unexpectedly
